Workbook

Sheet Dashboard
B2: ONLINE RETAIL — SALES DASHBOARD
B3: Online Retail II dataset · 4 Jan – 10 Feb 2010 · UK-based online giftware retailer
B5: TOTAL REVENUE | F5: ORDERS | J5: AVG ORDER VALUE | N5: UNITS SOLD | R5: CUSTOMERS
B6: =Calc!B4 -> 681758.99 | F6: =Calc!B5 -> 1347 | J6: =Calc!B6 -> 506.1314 | N6: =Calc!B7 -> 454011 | R6: =Calc!B8 -> 903

Sheet Data
A1: Invoice | B1: StockCode | C1: Description | D1: Quantity | E1: InvoiceDate | F1: Price | G1: Customer ID | H1: Country | I1: Revenue | J1: Month | K1: NewOrderFlag
A2: 493414 | B2: 21844 | C2: RETRO SPOT MUG | D2: 36 | E2: 40182.436 | F2: 2.55 | G2: 14590 | H2: United Kingdom | I2: 91.8 | J2: January | K2: =IF(A2<>A1,1,0) -> 1
A3: 493414 | B3: 21533 | C3: RETRO SPOT LARGE MILK JUG | D3: 12 | E3: 40182.436 | F3: 4.25 | G3: 14590 | H3: United Kingdom | I3: 51 | J3: January | K3: =IF(A3<>A2,1,0) -> 0
A4: 493414 | B4: 37508 | C4: NEW ENGLAND CERAMIC CAKE SERVER | D4: 2 | E4: 40182.436 | F4: 2.55 | G4: 14590 | H4: United Kingdom | I4: 5.1 | J4: January | K4: =IF(A4<>A3,1,0) -> 0
A5: 493414 | B5: 35001G | C5: HAND OPEN SHAPE GOLD | D5: 2 | E5: 40182.436 | F5: 4.25 | G5: 14590 | H5: United Kingdom | I5: 8.5 | J5: January | K5: =IF(A5<>A4,1,0) -> 0
A6: 493414 | B6: 21527 | C6: RETRO SPOT TRADITIONAL TEAPOT | D6: 12 | E6: 40182.436 | F6: 6.95 | G6: 14590 | H6: United Kingdom | I6: 83.4 | J6: January | K6: =IF(A6<>A5,1,0) -> 0
A7: 493414 | B7: 21531 | C7: RETRO SPOT SUGAR JAM BOWL | D7: 24 | E7: 40182.436 | F7: 2.1 | G7: 14590 | H7: United Kingdom | I7: 50.4 | J7: January | K7: =IF(A7<>A6,1,0) -> 0
A8: 493427 | B8: 82483 | C8: WOOD 2 DRAWER CABINET WHITE FINISH | D8: 4 | E8: 40182.447 | F8: 5.95 | G8: 13287 | H8: United Kingdom | I8: 23.8 | J8: January | K8: =IF(A8<>A7,1,0) -> 1
A9: 493427 | B9: 21681 | C9: GIANT MEDINA STAMPED METAL BOWL | D9: 2 | E9: 40182.447 | F9: 9.95 | G9: 13287 | H9: United Kingdom | I9: 19.9 | J9: January | K9: =IF(A9<>A8,1,0) -> 0
A10: 493427 | B10: 21682 | C10: LARGE MEDINA STAMPED METAL BOWL | D10: 4 | E10: 40182.447 | F10: 4.95 | G10: 13287 | H10: United Kingdom | I10: 19.8 | J10: January | K10: =IF(A10<>A9,1,0) -> 0
A11: 493427 | B11: 18096C | C11: WHITE ROUND PORCELAIN TLIGHT HOLDER | D11: 6 | E11: 40182.447 | F11: 2.55 | G11: 13287 | H11: United Kingdom | I11: 15.3 | J11: January | K11: =IF(A11<>A10,1,0) -> 0
A12: 493427 | B12: 21577 | C12: SAVE THE PLANET COTTON TOTE BAG | D12: 6 | E12: 40182.447 | F12: 2.25 | G12: 13287 | H12: United Kingdom | I12: 13.5 | J12: January | K12: =IF(A12<>A11,1,0) -> 0
A13: 493427 | B13: 21576 | C13: LETS GO SHOPPING COTTON TOTE BAG | D13: 6 | E13: 40182.447 | F13: 2.25 | G13: 13287 | H13: United Kingdom | I13: 13.5 | J13: January | K13: =IF(A13<>A12,1,0) -> 0
A14: 493427 | B14: 37447 | C14: CERAMIC CAKE DESIGN SPOTTED PLATE | D14: 12 | E14: 40182.447 | F14: 1.49 | G14: 13287 | H14: United Kingdom | I14: 17.88 | J14: January | K14: =IF(A14<>A13,1,0) -> 0
A15: 493427 | B15: 21232 | C15: STRAWBERRY CERAMIC TRINKET BOX | D15: 12 | E15: 40182.447 | F15: 1.25 | G15: 13287 | H15: United Kingdom | I15: 15 | J15: January | K15: =IF(A15<>A14,1,0) -> 0
A16: 493427 | B16: 79000 | C16: MOROCCAN TEA GLASS | D16: 12 | E16: 40182.447 | F16: 0.85 | G16: 13287 | H16: United Kingdom | I16: 10.2 | J16: January | K16: =IF(A16<>A15,1,0) -> 0
A17: 493427 | B17: 84499 | C17: BLACK FLOWER CANDLE PLATE | D17: 12 | E17: 40182.447 | F17: 0.85 | G17: 13287 | H17: United Kingdom | I17: 10.2 | J17: January | K17: =IF(A17<>A16,1,0) -> 0
A18: 493427 | B18: 72780 | C18: BLACK SILOUETTE CANDLE PLATE | D18: 12 | E18: 40182.447 | F18: 0.85 | G18: 13287 | H18: United Kingdom | I18: 10.2 | J18: January | K18: =IF(A18<>A17,1,0) -> 0
A19: 493427 | B19: 22214 | C19: CANDLE PLATE LACE WHITE | D19: 6 | E19: 40182.447 | F19: 2.55 | G19: 13287 | H19: United Kingdom | I19: 15.3 | J19: January | K19: =IF(A19<>A18,1,0) -> 0
A20: 493427 | B20: 72369A | C20: PINK CLEAR GLASS CANDLE PLATE | D20: 6 | E20: 40182.447 | F20: 1.25 | G20: 13287 | H20: United Kingdom | I20: 7.5 | J20: January | K20: =IF(A20<>A19,1,0) -> 0
A21: 493427 | B21: 21428 | C21: SET3 BOOK BOX GREEN GINGHAM FLOWER | D21: 4 | E21: 40182.447 | F21: 4.25 | G21: 13287 | H21: United Kingdom | I21: 17 | J21: January | K21: =IF(A21<>A20,1,0) -> 0
A22: 493427 | B22: 22178 | C22: VICTORIAN GLASS HANGING T-LIGHT | D22: 12 | E22: 40182.447 | F22: 1.25 | G22: 13287 | H22: United Kingdom | I22: 15 | J22: January | K22: =IF(A22<>A21,1,0) -> 0
A23: 493427 | B23: 84615 | C23: PINK ROUND BUTTERFLY MIRROR | D23: 2 | E23: 40182.447 | F23: 7.95 | G23: 13287 | H23: United Kingdom | I23: 15.9 | J23: January | K23: =IF(A23<>A22,1,0) -> 0
A24: 493427 | B24: 84686 | C24: BEACH HUT MIRROR | D24: 2 | E24: 40182.447 | F24: 4.25 | G24: 13287 | H24: United Kingdom | I24: 8.5 | J24: January | K24: =IF(A24<>A23,1,0) -> 0
A25: 493427 | B25: 21777 | C25: RECIPE BOX WITH METAL HEART | D25: 2 | E25: 40182.447 | F25: 7.95 | G25: 13287 | H25: United Kingdom | I25: 15.9 | J25: January | K25: =IF(A25<>A24,1,0) -> 0
A26: 493428 | B26: 84563A | C26: PINK & WHITE BREAKFAST TRAY | D26: 1 | E26: 40182.469 | F26: 5.95 | G26: 16550 | H26: United Kingdom | I26: 5.95 | J26: January | K26: =IF(A26<>A25,1,0) -> 1
A27: 493428 | B27: 84562A | C27: PINK/WHITE RIBBED MELAMINE JUG | D27: 1 | E27: 40182.469 | F27: 7.95 | G27: 16550 | H27: United Kingdom | I27: 7.95 | J27: January | K27: =IF(A27<>A26,1,0) -> 0
A28: 493428 | B28: 22347 | C28: PIZZA SLICE DISH | D28: 6 | E28: 40182.469 | F28: 1.25 | G28: 16550 | H28: United Kingdom | I28: 7.5 | J28: January | K28: =IF(A28<>A27,1,0) -> 0
A29: 493428 | B29: 21658 | C29: GLASS BEURRE DISH | D29: 2 | E29: 40182.469 | F29: 3.95 | G29: 16550 | H29: United Kingdom | I29: 7.9 | J29: January | K29: =IF(A29<>A28,1,0) -> 0
A30: 493428 | B30: 22084 | C30: PAPER CHAIN KIT EMPIRE | D30: 4 | E30: 40182.469 | F30: 2.95 | G30: 16550 | H30: United Kingdom | I30: 11.8 | J30: January | K30: =IF(A30<>A29,1,0) -> 0
A31: 493428 | B31: 22083 | C31: PAPER CHAIN KIT RETRO SPOT | D31: 6 | E31: 40182.469 | F31: 2.95 | G31: 16550 | H31: United Kingdom | I31: 17.7 | J31: January | K31: =IF(A31<>A30,1,0) -> 0
A32: 493428 | B32: 22197 | C32: POPCORN HOLDER , SMALL | D32: 6 | E32: 40182.469 | F32: 0.85 | G32: 16550 | H32: United Kingdom | I32: 5.1 | J32: January | K32: =IF(A32<>A31,1,0) -> 0
A33: 493428 | B33: 22198 | C33: POPCORN HOLDER , LARGE | D33: 6 | E33: 40182.469 | F33: 1.65 | G33: 16550 | H33: United Kingdom | I33: 9.9 | J33: January | K33: =IF(A33<>A32,1,0) -> 0
A34: 493428 | B34: 84988 | C34: SET OF 72 PINK HEART PAPER DOILIES | D34: 10 | E34: 40182.469 | F34: 1.45 | G34: 16550 | H34: United Kingdom | I34: 14.5 | J34: January | K34: =IF(A34<>A33,1,0) -> 0
A35: 493428 | B35: 21559 | C35: STRAWBERRY LUNCHBOX WITH CUTLERY | D35: 4 | E35: 40182.469 | F35: 2.55 | G35: 16550 | H35: United Kingdom | I35: 10.2 | J35: January | K35: =IF(A35<>A34,1,0) -> 0
A36: 493428 | B36: 21558 | C36: SKULL LUNCHBOX WITH CUTLERY | D36: 1 | E36: 40182.469 | F36: 2.55 | G36: 16550 | H36: United Kingdom | I36: 2.55 | J36: January | K36: =IF(A36<>A35,1,0) -> 0
A37: 493428 | B37: 22353 | C37: LUNCHBOX WITH CUTLERY FAIRY CAKES | D37: 4 | E37: 40182.469 | F37: 2.55 | G37: 16550 | H37: United Kingdom | I37: 10.2 | J37: January | K37: =IF(A37<>A36,1,0) -> 0
A38: 493428 | B38: 21561 | C38: DINOSAUR LUNCHBOX WITH CUTLERY | D38: 4 | E38: 40182.469 | F38: 2.55 | G38: 16550 | H38: United Kingdom | I38: 10.2 | J38: January | K38: =IF(A38<>A37,1,0) -> 0
A39: 493428 | B39: 21622 | C39: VINTAGE UNION JACK CUSHION COVER | D39: 6 | E39: 40182.469 | F39: 4.95 | G39: 16550 | H39: United Kingdom | I39: 29.7 | J39: January | K39: =IF(A39<>A38,1,0) -> 0
... A50: 493432 | B50: 21488 | C50: RED WHITE SCARF HOT WATER BOTTLE | D50: 1 | E50: 40182.521 | F50: 3.95 | G50: 14680 | H50: United Kingdom | I50: 3.95 | J50: January | K50: =IF(A50<>A49,1,0) -> 1
...

Sheet Calc
A1: Calculation sheet — all figures formula-driven from the Data sheet; feeds the Dashboard | AA1: UniqueCustomers
AA2: 12361
A3: KPIs | AA3: 12370
A4: Total Revenue | B4: =SUM(Data!$I$2:$I$29869) -> 681758.99 | AA4: 12373
A5: Orders | B5: =SUM(Data!$K$2:$K$29869) -> 1347 | AA5: 12396
A6: Avg Order Value | B6: =B4/B5 -> 506.1314 | AA6: 12402
A7: Units Sold | B7: =SUM(Data!$D$2:$D$29869) -> 454011 | AA7: 12406
A8: Customers | B8: =COUNTA($AA$2:$AA$904) -> 903 | AA8: 12417
A9: Countries | B9: =COUNTA($K$15:$K$34) -> 20 | AA9: 12431
A10: UK Revenue | B10: =SUMIFS(Data!$I$2:$I$29869,Data!$H$2:$H$29869,"United Kingdom") -> 530178.44 | AA10: 12437
A11: International Revenue | B11: =B4-B10 -> 151580.55 | AA11: 12439
AA12: 12468
AA13: 12470
A14: Date | B14: Revenue | D14: Product | E14: Revenue | G14: Rank | H14: Product | I14: Revenue | K14: Country | L14: Revenue | N14: Intl Country | O14: Revenue | Q14: Rank | R14: Country | S14: Revenue | U14: Segment | V14: Revenue | AA14: 12471
A15: 40182 | B15: =SUMIFS(Data!$I$2:$I$29869,Data!$E$2:$E$29869,">="&A15,Data!$E$2:$E$29869,"<"&A15+1) -> 13405.54 | D15: DOORMAT UNION JACK GUNS AND ROSES | E15: =SUMIFS(Data!$I$2:$I$29869,Data!$C$2:$C$29869,D15) -> 984.75 | G15: 10 | H15: =INDEX($D$15:$D$2552,MATCH(I15,$E$15:$E$2552,0)) -> TEA TIME CAKE STAND IN GIFT BOX | I15: =LARGE($E$15:$E$2552,G15) -> 3592 | K15: Austria | L15: =SUMIFS(Data!$I$2:$I$29869,Data!$H$2:$H$29869,K15) -> 760.86 | N15: Austria | O15: =SUMIFS(Data!$I$2:$I$29869,Data!$H$2:$H$29869,N15) -> 760.86 | Q15: 1 | R15: =INDEX($N$15:$N$33,MATCH(S15,$O$15:$O$33,0)) -> EIRE | S15: =LARGE($O$15:$O$33,Q15) -> 67781.15 | U15: United Kingdom | V15: =B10 -> 530178.44 | AA15: 12472
A16: 40183 | B16: =SUMIFS(Data!$I$2:$I$29869,Data!$E$2:$E$29869,">="&A16,Data!$E$2:$E$29869,"<"&A16+1) -> 19136.14 | D16: 3 STRIPEY MICE FELTCRAFT | E16: =SUMIFS(Data!$I$2:$I$29869,Data!$C$2:$C$29869,D16) -> 255.45 | G16: 9 | H16: =INDEX($D$15:$D$2552,MATCH(I16,$E$15:$E$2552,0)) -> SET/5 RED SPOTTY LID GLASS BOWLS | I16: =LARGE($E$15:$E$2552,G16) -> 3824.65 | K16: Belgium | L16: =SUMIFS(Data!$I$2:$I$29869,Data!$H$2:$H$29869,K16) -> 1615.72 | N16: Belgium | O16: =SUMIFS(Data!$I$2:$I$29869,Data!$H$2:$H$29869,N16) -> 1615.72 | Q16: 2 | R16: =INDEX($N$15:$N$33,MATCH(S16,$O$15:$O$33,0)) -> Netherlands | S16: =LARGE($O$15:$O$33,Q16) -> 29404.27 | U16: International | V16: =B11 -> 151580.55 | AA16: 12483
A17: 40184 | B17: =SUMIFS(Data!$I$2:$I$29869,Data!$E$2:$E$29869,">="&A17,Data!$E$2:$E$29869,"<"&A17+1) -> 8736.94 | D17: ANIMAL STICKERS | E17: =SUMIFS(Data!$I$2:$I$29869,Data!$C$2:$C$29869,D17) -> 25.41 | G17: 8 | H17: =INDEX($D$15:$D$2552,MATCH(I17,$E$15:$E$2552,0)) -> RED WOOLLY HOTTIE WHITE HEART. | I17: =LARGE($E$15:$E$2552,G17) -> 3873.95 | K17: Channel Islands | L17: =SUMIFS(Data!$I$2:$I$29869,Data!$H$2:$H$29869,K17) -> 838.75 | N17: Channel Islands | O17: =SUMIFS(Data!$I$2:$I$29869,Data!$H$2:$H$29869,N17) -> 838.75 | Q17: 3 | R17: =INDEX($N$15:$N$33,MATCH(S17,$O$15:$O$33,0)) -> Germany | S17: =LARGE($O$15:$O$33,Q17) -> 16105.5 | AA17: 12484
A18: 40185 | B18: =SUMIFS(Data!$I$2:$I$29869,Data!$E$2:$E$29869,">="&A18,Data!$E$2:$E$29869,"<"&A18+1) -> 73016.23 | D18: BLACK PIRATE TREASURE CHEST | E18: =SUMIFS(Data!$I$2:$I$29869,Data!$C$2:$C$29869,D18) -> 9.9 | G18: 7 | H18: =INDEX($D$15:$D$2552,MATCH(I18,$E$15:$E$2552,0)) -> EDWARDIAN PARASOL BLACK | I18: =LARGE($E$15:$E$2552,G18) -> 4593.25 | K18: Cyprus | L18: =SUMIFS(Data!$I$2:$I$29869,Data!$H$2:$H$29869,K18) -> 76.52 | N18: Cyprus | O18: =SUMIFS(Data!$I$2:$I$29869,Data!$H$2:$H$29869,N18) -> 76.52 | Q18: 4 | R18: =INDEX($N$15:$N$33,MATCH(S18,$O$15:$O$33,0)) -> France | S18: =LARGE($O$15:$O$33,Q18) -> 11834.81 | AA18: 12490
A19: 40186 | B19: =SUMIFS(Data!$I$2:$I$29869,Data!$E$2:$E$29869,">="&A19,Data!$E$2:$E$29869,"<"&A19+1) -> 28279.76 | D19: BROWN PIRATE TREASURE CHEST | E19: =SUMIFS(Data!$I$2:$I$29869,Data!$C$2:$C$29869,D19) -> 13.2 | G19: 6 | H19: =INDEX($D$15:$D$2552,MATCH(I19,$E$15:$E$2552,0)) -> EDWARDIAN PARASOL RED | I19: =LARGE($E$15:$E$2552,G19) -> 4610.6 | K19: Denmark | L19: =SUMIFS(Data!$I$2:$I$29869,Data!$H$2:$H$29869,K19) -> 7870.6 | N19: Denmark | O19: =SUMIFS(Data!$I$2:$I$29869,Data!$H$2:$H$29869,N19) -> 7870.6 | Q19: 5 | R19: =INDEX($N$15:$N$33,MATCH(S19,$O$15:$O$33,0)) -> Denmark | S19: =LARGE($O$15:$O$33,Q19) -> 7870.6 | AA19: 12500
A20: 40187 | B20: =SUMIFS(Data!$I$2:$I$29869,Data!$E$2:$E$29869,">="&A20,Data!$E$2:$E$29869,"<"&A20+1) -> 0 | D20: CAMPHOR WOOD PORTOBELLO MUSHROOM | E20: =SUMIFS(Data!$I$2:$I$29869,Data!$C$2:$C$29869,D20) -> 15 | G20: 5 | H20: =INDEX($D$15:$D$2552,MATCH(I20,$E$15:$E$2552,0)) -> RED HANGING HEART T-LIGHT HOLDER | I20: =LARGE($E$15:$E$2552,G20) -> 5016.8 | K20: EIRE | L20: =SUMIFS(Data!$I$2:$I$29869,Data!$H$2:$H$29869,K20) -> 67781.15 | N20: EIRE | O20: =SUMIFS(Data!$I$2:$I$29869,Data!$H$2:$H$29869,N20) -> 67781.15 | Q20: 6 | R20: =INDEX($N$15:$N$33,MATCH(S20,$O$15:$O$33,0)) -> Greece | S20: =LARGE($O$15:$O$33,Q20) -> 4798.35 | AA20: 12510
A21: 40188 | B21: =SUMIFS(Data!$I$2:$I$29869,Data!$E$2:$E$29869,">="&A21,Data!$E$2:$E$29869,"<"&A21+1) -> 23136.08 | D21: CHERRY BLOSSOM DECORATIVE FLASK | E21: =SUMIFS(Data!$I$2:$I$29869,Data!$C$2:$C$29869,D21) -> 929.85 | G21: 4 | H21: =INDEX($D$15:$D$2552,MATCH(I21,$E$15:$E$2552,0)) -> RETRO SPOT CAKE STAND | I21: =LARGE($E$15:$E$2552,G21) -> 5563.8 | K21: Finland | L21: =SUMIFS(Data!$I$2:$I$29869,Data!$H$2:$H$29869,K21) -> 738.18 | N21: Finland | O21: =SUMIFS(Data!$I$2:$I$29869,Data!$H$2:$H$29869,N21) -> 738.18 | Q21: 7 | R21: =INDEX($N$15:$N$33,MATCH(S21,$O$15:$O$33,0)) -> Spain | S21: =LARGE($O$15:$O$33,Q21) -> 2519.54 | AA21: 12523
A22: 40189 | B22: =SUMIFS(Data!$I$2:$I$29869,Data!$E$2:$E$29869,">="&A22,Data!$E$2:$E$29869,"<"&A22+1) -> 18208.35 | D22: FLAMINGO LIGHTS | E22: =SUMIFS(Data!$I$2:$I$29869,Data!$C$2:$C$29869,D22) -> 461.4 | G22: 3 | H22: =INDEX($D$15:$D$2552,MATCH(I22,$E$15:$E$2552,0)) -> DOOR MAT UNION FLAG | I22: =LARGE($E$15:$E$2552,G22) -> 5755.96 | K22: France | L22: =SUMIFS(Data!$I$2:$I$29869,Data!$H$2:$H$29869,K22) -> 11834.81 | N22: France | O22: =SUMIFS(Data!$I$2:$I$29869,Data!$H$2:$H$29869,N22) -> 11834.81 | Q22: 8 | R22: =INDEX($N$15:$N$33,MATCH(S22,$O$15:$O$33,0)) -> USA | S22: =LARGE($O$15:$O$33,Q22) -> 2284.59 | AA22: 12524
A23: 40190 | B23: =SUMIFS(Data!$I$2:$I$29869,Data!$E$2:$E$29869,">="&A23,Data!$E$2:$E$29869,"<"&A23+1) -> 38573.28 | D23: HOME SWEET HOME BLACKBOARD | E23: =SUMIFS(Data!$I$2:$I$29869,Data!$C$2:$C$29869,D23) -> 392.11 | G23: 2 | H23: =INDEX($D$15:$D$2552,MATCH(I23,$E$15:$E$2552,0)) -> JUMBO BAG RED WHITE SPOTTY | I23: =LARGE($E$15:$E$2552,G23) -> 7241.4 | K23: Germany | L23: =SUMIFS(Data!$I$2:$I$29869,Data!$H$2:$H$29869,K23) -> 16105.5 | N23: Germany | O23: =SUMIFS(Data!$I$2:$I$29869,Data!$H$2:$H$29869,N23) -> 16105.5 | AA23: 12531
A24: 40191 | B24: =SUMIFS(Data!$I$2:$I$29869,Data!$E$2:$E$29869,">="&A24,Data!$E$2:$E$29869,"<"&A24+1) -> 11202.59 | D24: IVORY PAPER CUP CAKE CASES | E24: =SUMIFS(Data!$I$2:$I$29869,Data!$C$2:$C$29869,D24) -> 234.6 | G24: 1 | H24: =INDEX($D$15:$D$2552,MATCH(I24,$E$15:$E$2552,0)) -> WHITE HANGING HEART T-LIGHT HOLDER | I24: =LARGE($E$15:$E$2552,G24) -> 16911.55 | K24: Greece | L24: =SUMIFS(Data!$I$2:$I$29869,Data!$H$2:$H$29869,K24) -> 4798.35 | N24: Greece | O24: =SUMIFS(Data!$I$2:$I$29869,Data!$H$2:$H$29869,N24) -> 4798.35 | AA24: 12540
A25: 40192 | B25: =SUMIFS(Data!$I$2:$I$29869,Data!$E$2:$E$29869,">="&A25,Data!$E$2:$E$29869,"<"&A25+1) -> 23820.97 | D25: LARGE SKULL WINDMILL | E25: =SUMIFS(Data!$I$2:$I$29869,Data!$C$2:$C$29869,D25) -> 12.6 | K25: Japan | L25: =SUMIFS(Data!$I$2:$I$29869,Data!$H$2:$H$29869,K25) -> 162.61 | N25: Japan | O25: =SUMIFS(Data!$I$2:$I$29869,Data!$H$2:$H$29869,N25) -> 162.61 | AA25: 12549
A26: 40193 | B26: =SUMIFS(Data!$I$2:$I$29869,Data!$E$2:$E$29869,">="&A26,Data!$E$2:$E$29869,"<"&A26+1) -> 13339.54 | D26: NEW BAROQUE BLACK BOXES | E26: =SUMIFS(Data!$I$2:$I$29869,Data!$C$2:$C$29869,D26) -> 38.25 | K26: Malta | L26: =SUMIFS(Data!$I$2:$I$29869,Data!$H$2:$H$29869,K26) -> 818.19 | N26: Malta | O26: =SUMIFS(Data!$I$2:$I$29869,Data!$H$2:$H$29869,N26) -> 818.19 | AA26: 12589
A27: 40194 | B27: =SUMIFS(Data!$I$2:$I$29869,Data!$E$2:$E$29869,">="&A27,Data!$E$2:$E$29869,"<"&A27+1) -> 0 | D27: PEACE WOODEN BLOCK LETTERS | E27: =SUMIFS(Data!$I$2:$I$29869,Data!$C$2:$C$29869,D27) -> 118.15 | K27: Netherlands | L27: =SUMIFS(Data!$I$2:$I$29869,Data!$H$2:$H$29869,K27) -> 29404.27 | N27: Netherlands | O27: =SUMIFS(Data!$I$2:$I$29869,Data!$H$2:$H$29869,N27) -> 29404.27 | AA27: 12600
A28: 40195 | B28: =SUMIFS(Data!$I$2:$I$29869,Data!$E$2:$E$29869,">="&A28,Data!$E$2:$E$29869,"<"&A28+1) -> 17548.29 | D28: RED/WHITE DOT MINI CASES | E28: =SUMIFS(Data!$I$2:$I$29869,Data!$C$2:$C$29869,D28) -> 1439.9 | K28: Portugal | L28: =SUMIFS(Data!$I$2:$I$29869,Data!$H$2:$H$29869,K28) -> 374.83 | N28: Portugal | O28: =SUMIFS(Data!$I$2:$I$29869,Data!$H$2:$H$29869,N28) -> 374.83 | AA28: 12621
A29: 40196 | B29: =SUMIFS(Data!$I$2:$I$29869,Data!$E$2:$E$29869,">="&A29,Data!$E$2:$E$29869,"<"&A29+1) -> 12132.69 | D29: RIDGED GLASS T-LIGHT HOLDER | E29: =SUMIFS(Data!$I$2:$I$29869,Data!$C$2:$C$29869,D29) -> 31.2 | K29: RSA | L29: =SUMIFS(Data!$I$2:$I$29869,Data!$H$2:$H$29869,K29) -> 931.43 | N29: RSA | O29: =SUMIFS(Data!$I$2:$I$29869,Data!$H$2:$H$29869,N29) -> 931.43 | AA29: 12623
A30: 40197 | B30: =SUMIFS(Data!$I$2:$I$29869,Data!$E$2:$E$29869,">="&A30,Data!$E$2:$E$29869,"<"&A30+1) -> 21885.471 | D30: SILVER CHERRY LIGHTS | E30: =SUMIFS(Data!$I$2:$I$29869,Data!$C$2:$C$29869,D30) -> 222.75 | K30: Spain | L30: =SUMIFS(Data!$I$2:$I$29869,Data!$H$2:$H$29869,K30) -> 2519.54 | N30: Spain | O30: =SUMIFS(Data!$I$2:$I$29869,Data!$H$2:$H$29869,N30) -> 2519.54 | AA30: 12631
A31: 40198 | B31: =SUMIFS(Data!$I$2:$I$29869,Data!$E$2:$E$29869,">="&A31,Data!$E$2:$E$29869,"<"&A31+1) -> 11852.76 | D31: SILVER T-LIGHT SETTING | E31: =SUMIFS(Data!$I$2:$I$29869,Data!$C$2:$C$29869,D31) -> 91.65 | K31: Sweden | L31: =SUMIFS(Data!$I$2:$I$29869,Data!$H$2:$H$29869,K31) -> 1629.55 | N31: Sweden | O31: =SUMIFS(Data!$I$2:$I$29869,Data!$H$2:$H$29869,N31) -> 1629.55 | AA31: 12644
A32: 40199 | B32: =SUMIFS(Data!$I$2:$I$29869,Data!$E$2:$E$29869,">="&A32,Data!$E$2:$E$29869,"<"&A32+1) -> 27391.96 | D32: WHITE BAMBOO RIBS LAMPSHADE | E32: =SUMIFS(Data!$I$2:$I$29869,Data!$C$2:$C$29869,D32) -> 112.56 | K32: USA | L32: =SUMIFS(Data!$I$2:$I$29869,Data!$H$2:$H$29869,K32) -> 2284.59 | N32: USA | O32: =SUMIFS(Data!$I$2:$I$29869,Data!$H$2:$H$29869,N32) -> 2284.59 | AA32: 12645
A33: 40200 | B33: =SUMIFS(Data!$I$2:$I$29869,Data!$E$2:$E$29869,">="&A33,Data!$E$2:$E$29869,"<"&A33+1) -> 27636.09 | D33: WHITE CHERRY LIGHTS | E33: =SUMIFS(Data!$I$2:$I$29869,Data!$C$2:$C$29869,D33) -> 3532.2 | K33: United Kingdom | L33: =SUMIFS(Data!$I$2:$I$29869,Data!$H$2:$H$29869,K33) -> 530178.44 | N33: Unspecified | O33: =SUMIFS(Data!$I$2:$I$29869,Data!$H$2:$H$29869,N33) -> 1035.1 | AA33: 12647
A34: 40201 | B34: =SUMIFS(Data!$I$2:$I$29869,Data!$E$2:$E$29869,">="&A34,Data!$E$2:$E$29869,"<"&A34+1) -> 0 | D34: 12 DAISY PEGS IN WOOD BOX | E34: =SUMIFS(Data!$I$2:$I$29869,Data!$C$2:$C$29869,D34) -> 130.35 | K34: Unspecified | L34: =SUMIFS(Data!$I$2:$I$29869,Data!$H$2:$H$29869,K34) -> 1035.1 | AA34: 12648
A35: 40202 | B35: =SUMIFS(Data!$I$2:$I$29869,Data!$E$2:$E$29869,">="&A35,Data!$E$2:$E$29869,"<"&A35+1) -> 15637.72 | D35: 12 EGG HOUSE PAINTED WOOD | E35: =SUMIFS(Data!$I$2:$I$29869,Data!$C$2:$C$29869,D35) -> 1597.1 | AA35: 12649
A36: 40203 | B36: =SUMIFS(Data!$I$2:$I$29869,Data!$E$2:$E$29869,">="&A36,Data!$E$2:$E$29869,"<"&A36+1) -> 18295.24 | D36: 12 IVORY ROSE PEG PLACE SETTINGS | E36: =SUMIFS(Data!$I$2:$I$29869,Data!$C$2:$C$29869,D36) -> 75 | AA36: 12663
A37: 40204 | B37: =SUMIFS(Data!$I$2:$I$29869,Data!$E$2:$E$29869,">="&A37,Data!$E$2:$E$29869,"<"&A37+1) -> 34931.7 | D37: 12 MINI TOADSTOOL PEGS | E37: =SUMIFS(Data!$I$2:$I$29869,Data!$C$2:$C$29869,D37) -> 90 | AA37: 12665
A38: 40205 | B38: =SUMIFS(Data!$I$2:$I$29869,Data!$E$2:$E$29869,">="&A38,Data!$E$2:$E$29869,"<"&A38+1) -> 23758.02 | D38: 12 PENCILS SMALL TUBE POSY | E38: =SUMIFS(Data!$I$2:$I$29869,Data!$C$2:$C$29869,D38) -> 29.9 | AA38: 12668
A39: 40206 | B39: =SUMIFS(Data!$I$2:$I$29869,Data!$E$2:$E$29869,">="&A39,Data!$E$2:$E$29869,"<"&A39+1) -> 18929.43 | D39: 12 PENCILS SMALL TUBE RED SPOTTY | E39: =SUMIFS(Data!$I$2:$I$29869,Data!$C$2:$C$29869,D39) -> 315.9 | AA39: 12678
A40: 40207 | B40: =SUMIFS(Data!$I$2:$I$29869,Data!$E$2:$E$29869,">="&A40,Data!$E$2:$E$29869,"<"&A40+1) -> 16358.391 | D40: 12 PENCILS SMALL TUBE SKULL | E40: =SUMIFS(Data!$I$2:$I$29869,Data!$C$2:$C$29869,D40) -> 304.2 | AA40: 12681
...
